<?xml version="1.0"?>
<robot name="my_robot">
    <link name="link1">
        <visual>
            <geometry>
                <box size="0.15 0.15 0.3"/>
            </geometry>
        </visual>
        <collision>
            <geometry>
                <box size="0.15 0.15 0.3"/>
            </geometry>
        </collision>
        <inertial>
            <mass value="1.0"/>
            <inertia ixx="0.01" ixy="0.0" ixz="0.0" iyy="0.01" iyz="0.0" izz="0.01"/>
            <origin xyz="0.0 0.0 0.0" rpy="0.0 0.0 0.0"/>
        </inertial>
    </link>
    <link name="link2">
        <visual>
            <geometry>
                <box size="0.1 0.1 0.1"/>
            </geometry>
        </visual>
        <collision>
            <geometry>
                <box size="0.1 0.1 0.1"/>
            </geometry>
        </collision>
        <inertial>
            <mass value="1.0"/>
            <inertia ixx="0.01" ixy="0.0" ixz="0.0" iyy="0.01" iyz="0.0" izz="0.01"/>
            <origin xyz="0.0 0.0 0.0" rpy="0.0 0.0 0.0"/>
        </inertial>
    </link>

    <joint name="joint1" type="revolute">
        <parent link="link1"/>
        <child link="link2"/>
        <axis xyz="0.0 0.0 1.0"/>
        <dynamics damping="1.0" friction="0.5"/>
        <limit effort="5.0" lower="-1e9" upper="1e9" velocity="5.0"/>
        <origin xyz="0.0 0.0 0.2" rpy="0.0 0.0 0.0"/>
    </joint>

    <transmission name="joint1_trans">
        <type>transmission_interface/SimpleTransmission</type>
        <actuator name="joint1_motor">
            <hardwareInterface>hardware_interface/EffortJointInterface</hardwareInterface>
            <mechanicalReduction>19.2032</mechanicalReduction>
        </actuator>
        <joint name="joint1">
            <hardwareInterface>hardware_interface/EffortJointInterface</hardwareInterface>
        </joint>
    </transmission>

    <gazebo>
        <plugin name="rm_ros_control" filename="librm_robot_hw_sim.so">
            <robotNamespace>/</robotNamespace>
            <robotSimType>rm_gazebo/RmRobotHWSim</robotSimType>
        </plugin>
    </gazebo>

</robot>
